Workbook

Sheet Sheet1 (3)
B1: TOTAL
C2: Sales | D2: GCS1 | E2: ACS2 | F2: ACS (delta)
B3: 2023 | C3: 481513 | D3: 41613 | E3: =C3/D3 -> 11.571216
B4: 2024 | C4: 494078 | D4: 42138 | E4: =C4/D4 -> 11.725236
B5: YoY | C5: =C4/C3-1 -> 0.02609483 | D5: =D4/D3-1 -> 0.01261625 | E5: =E4/E3-1 -> 0.01331065 | F5: =E4-E3 -> 0.1540204
B6: Contribution | C6: =SUM(D6:E6) -> 0.02609483 | D6: =D5+0.5*(D5*E5) -> 0.012700215 | E6: =E5+0.5*(E5*D5) -> 0.013394615
B8: ACS Mix contrib3 | E8: =SUM(T22:T27) -> 0.031511544
B9: ACS Within contrib4 | E9: =SUM(U22:U27) -> -0.018200894
B11: 1 Traffic Effect: GCS contribution (pp) = Base-year GCS share × Within-daypart YoY growth
B12: 2 Ticket Effect: ACS contribution = ACS mix contribution + ACS within contribution
B13: 3 Customer shift effect: ACS mix contribution = Change in GCS share × Base-period segment ACS; Holding segment-level ACS constant as last year, customers moved toward/away higher-ticket segment
B14: 4 Within-segment ticket pressure: ACS within contribution = Current-period GCS share × Change in segment ACS
B17: SALES | I17: GCS | R17: ACS
D19: 2023 | F19: 2024 | K19: 2023 | M19: 2024 | O19: YoY
C20: Total contrib PP | D20: Value | E20: Share | F20: Value | G20: Share | J20: Total contrib PP | K20: Value | L20: Share | M20: Value | N20: Share | O20: YoY % | P20: YoY (delta) | S20: Total contrib PP | T20: Mix contrib PP | U20: Within contrib PP | V20: Total contrib | W20: Mix contrib | X20: Within contrib | Y20: ACS value
A21: Daypart | B21: Daypart | I21: Daypart | R21: Daypart | Y21: 2023 | Z21: 2024 | AA21: ACS (delta)
B22: Breakfast | C22: =J22+S22 -> 0.066881044 | D22: 120378.25 | E22: =D22/$C$3 -> 0.25 | F22: 138341.84 | G22: =F22/$C$4 -> 0.28 | I22: Breakfast | J22: =L22*O22 -> 0.033154062 | K22: 9154.86 | L22: =K22/$D$3 -> 0.22 | M22: 10534.5 | N22: =M22/$D$4 -> 0.25 | O22: =M22/K22-1 -> 0.15070028 | P22: =N22-L22 -> 0.03 | R22: Breakfast | S22: =V22/$E$3 -> 0.033726982 | T22: =W22/$E$3 -> 0.034090909 | U22: =X22/$E$3 -> -0.00036392708 | V22: =SUM(W22:X22) -> 0.39026218 | W22: =P22*Y22 -> 0.39447326 | X22: =N22*AA22 -> -0.0042110788 | Y22: =D22/K22 -> 13.149109 | Z22: =F22/M22 -> 13.132264 | AA22: =Z22-Y22 -> -0.016844315
B23: Lunch | C23: =J23+S23 -> 0.066628719 | D23: 120378.25 | E23: =D23/$C$3 -> 0.25 | F23: 138341.84 | G23: =F23/$C$4 -> 0.28 | I23: Lunch | J23: =L23*O23 -> 0.032901737 | K23: 8322.6 | L23: =K23/$D$3 -> 0.2 | M23: 9691.74 | N23: =M23/$D$4 -> 0.23 | O23: =M23/K23-1 -> 0.16450869 | P23: =N23-L23 -> 0.03 | R23: Lunch | S23: =V23/$E$3 -> 0.033726982 | T23: =W23/$E$3 -> 0.0375 | U23: =X23/$E$3 -> -0.003773018 | V23: =SUM(W23:X23) -> 0.39026218 | W23: =P23*Y23 -> 0.43392059 | X23: =N23*AA23 -> -0.043658405 | Y23: =D23/K23 -> 14.46402 | Z23: =F23/M23 -> 14.274201 | AA23: =Z23-Y23 -> -0.18981915
B24: Snack | C24: =J24+S24 -> -0.039096031 | D24: 24075.65 | E24: =D24/$C$3 -> 0.05 | F24: 14822.34 | G24: =F24/$C$4 -> 0.03 | I24: Snack | J24: =L24*O24 -> -0.01949535 | K24: 2496.78 | L24: =K24/$D$3 -> 0.06 | M24: 1685.52 | N24: =M24/$D$4 -> 0.04 | O24: =M24/K24-1 -> -0.3249225 | P24: =N24-L24 -> -0.02 | R24: Snack | S24: =V24/$E$3 -> -0.01960068 | T24: =W24/$E$3 -> -0.016666667 | U24: =X24/$E$3 -> -0.0029340138 | V24: =SUM(W24:X24) -> -0.2268037 | W24: =P24*Y24 -> -0.1928536 | X24: =N24*AA24 -> -0.033950107 | Y24: =D24/K24 -> 9.6426798 | Z24: =F24/M24 -> 8.7939271 | AA24: =Z24-Y24 -> -0.84875267
B25: Dinner | C25: =J25+S25 -> -0.092887463 | D25: 144453.9 | E25: =D25/$C$3 -> 0.3 | F25: 123519.5 | G25: =F25/$C$4 -> 0.25 | I25: Dinner | J25: =L25*O25 -> -0.046215125 | K25: 14564.55 | L25: =K25/$D$3 -> 0.35 | M25: 12641.4 | N25: =M25/$D$4 -> 0.3 | O25: =M25/K25-1 -> -0.13204321 | P25: =N25-L25 -> -0.05 | R25: Dinner | S25: =V25/$E$3 -> -0.046672337 | T25: =W25/$E$3 -> -0.042857143 | U25: =X25/$E$3 -> -0.0038151946 | V25: =SUM(W25:X25) -> -0.54005569 | W25: =P25*Y25 -> -0.49590925 | X25: =N25*AA25 -> -0.04414644 | Y25: =D25/K25 -> 9.9181849 | Z25: =F25/M25 -> 9.7710301 | AA25: =Z25-Y25 -> -0.1471548
B26: Evening | C26: =J26+S26 -> 0.073258222 | D26: 48151.3 | E26: =D26/$C$3 -> 0.1 | F26: 74111.7 | G26: =F26/$C$4 -> 0.15 | I26: Evening | J26: =L26*O26 -> 0.021261625 | K26: 3329.04 | L26: =K26/$D$3 -> 0.08 | M26: 4213.8 | N26: =M26/$D$4 -> 0.1 | O26: =M26/K26-1 -> 0.26577031 | P26: =N26-L26 -> 0.02 | R26: Evening | S26: =V26/$E$3 -> 0.051996598 | T26: =W26/$E$3 -> 0.025 | U26: =X26/$E$3 -> 0.026996598 | V26: =SUM(W26:X26) -> 0.60166385 | W26: =P26*Y26 -> 0.28928039 | X26: =N26*AA26 -> 0.31238345 | Y26: =D26/K26 -> 14.46402 | Z26: =F26/M26 -> 17.587854 | AA26: =Z26-Y26 -> 3.1238345
B27: Late Night | C27: =J27+S27 -> -0.048857594 | D27: 24075.65 | E27: =D27/$C$3 -> 0.05 | F27: 4940.78 | G27: =F27/$C$4 -> 0.01 | I27: Late Night | J27: =L27*O27 -> -0.0089907 | K27: 3745.17 | L27: =K27/$D$3 -> 0.09 | M27: 3371.04 | N27: =M27/$D$4 -> 0.08 | O27: =M27/K27-1 -> -0.099896667 | P27: =N27-L27 -> -0.01 | R27: Late Night | S27: =V27/$E$3 -> -0.039866893 | T27: =W27/$E$3 -> -0.0055555556 | U27: =X27/$E$3 -> -0.034311338 | V27: =SUM(W27:X27) -> -0.46130843 | W27: =P27*Y27 -> -0.064284532 | X27: =N27*AA27 -> -0.39702389 | Y27: =D27/K27 -> 6.4284532 | Z27: =F27/M27 -> 1.4656545 | AA27: =Z27-Y27 -> -4.9627987
B28: Total | C28: =SUM(C22:C27) -> 0.0259269 | D28: =SUM(D22:D27) -> 481513 | E28: =SUM(E22:E27) -> 1 | F28: =SUM(F22:F27) -> 494078 | G28: =SUM(G22:G27) -> 1 | I28: Total | J28: =SUM(J22:J27) -> 0.01261625 | K28: =SUM(K22:K27) -> 41613 | L28: =SUM(L22:L27) -> 1 | M28: =SUM(M22:M27) -> 42138 | N28: =SUM(N22:N27) -> 1 | R28: Total | S28: =SUM(S22:S27) -> 0.01331065 | V28: =SUM(V22:V27) -> 0.1540204

Sheet Sheet2
H2: Contribution | I2: 2023 share | J2: 2024 YoY %
F3: Dayparts | G3: Breakfast | H3: =TEXT('Sheet1 (2)'!I35*100,"0.0") & " PP" -> 3.3 PP | I3: ='Sheet1 (2)'!K35 -> 0.22 | J3: ='Sheet1 (2)'!N35 -> 0.15070028
G4: Lunch | H4: =TEXT('Sheet1 (2)'!I36*100,"0.0") & " PP" -> 3.3 PP | I4: ='Sheet1 (2)'!K36 -> 0.2 | J4: ='Sheet1 (2)'!N36 -> 0.16450869
D5: GCS | G5: Snack | H5: =TEXT('Sheet1 (2)'!I37*100,"0.0") & " PP" -> -1.9 PP | I5: ='Sheet1 (2)'!K37 -> 0.06 | J5: ='Sheet1 (2)'!N37 -> -0.3249225
D6: =TEXT('Sheet1 (2)'!C6*100,"0.00") & " PP" -> 1.27 PP | G6: Dinner | H6: =TEXT('Sheet1 (2)'!I38*100,"0.0") & " PP" -> -4.6 PP | I6: ='Sheet1 (2)'!K38 -> 0.35 | J6: ='Sheet1 (2)'!N38 -> -0.13204321
D7: Traffic effect | G7: Evening | H7: =TEXT('Sheet1 (2)'!I39*100,"0.0") & " PP" -> 2.1 PP | I7: ='Sheet1 (2)'!K39 -> 0.08 | J7: ='Sheet1 (2)'!N39 -> 0.26577031
G8: Late Night | H8: =TEXT('Sheet1 (2)'!I40*100,"0.0") & " PP" -> -0.9 PP | I8: ='Sheet1 (2)'!K40 -> 0.09 | J8: ='Sheet1 (2)'!N40 -> -0.099896667
B10: SALES | H10: Contribution | I10: 2023 share | J10: 2024 YoY %
B11: ='Sheet1 (2)'!B5 -> 0.02609483 | F11: Segment2 | G11: Breakfast | H11: =TEXT('Sheet1 (2)'!I46*100,"0.0") & " PP" -> 0.0 PP | I11: ='Sheet1 (2)'!K46 -> 0 | J11: ='Sheet1 (2)'!N46 -> 0
B12: YoY 23 vs 24 | G12: Lunch | H12: =TEXT('Sheet1 (2)'!I47*100,"0.0") & " PP" -> 0.0 PP | I12: ='Sheet1 (2)'!K47 -> 0 | J12: ='Sheet1 (2)'!N47 -> 0
G13: Snack | H13: =TEXT('Sheet1 (2)'!I48*100,"0.0") & " PP" -> 0.0 PP | I13: ='Sheet1 (2)'!K48 -> 0 | J13: ='Sheet1 (2)'!N48 -> 0
G14: Dinner | H14: =TEXT('Sheet1 (2)'!I49*100,"0.0") & " PP" -> 0.0 PP | I14: ='Sheet1 (2)'!K49 -> 0 | J14: ='Sheet1 (2)'!N49 -> 0
G15: Evening | H15: =TEXT('Sheet1 (2)'!I50*100,"0.0") & " PP" -> 0.0 PP | I15: ='Sheet1 (2)'!K50 -> 0 | J15: ='Sheet1 (2)'!N50 -> 0
G16: Late Night | H16: =TEXT('Sheet1 (2)'!I51*100,"0.0") & " PP" -> 0.0 PP | I16: ='Sheet1 (2)'!K51 -> 0 | J16: ='Sheet1 (2)'!N51 -> 0
H18: Contribution | I18: 2023 share | J18: 2024 YoY %
F19: Segment3 | G19: Breakfast | H19: =TEXT('Sheet1 (2)'!I54*100,"0.0") & " PP" -> 0.0 PP | I19: ='Sheet1 (2)'!K54 -> 0 | J19: ='Sheet1 (2)'!N54 -> 0
G20: Lunch | H20: =TEXT('Sheet1 (2)'!I55*100,"0.0") & " PP" -> 0.0 PP | I20: ='Sheet1 (2)'!K55 -> 0 | J20: ='Sheet1 (2)'!N55 -> 0
G21: Snack | H21: =TEXT('Sheet1 (2)'!I56*100,"0.0") & " PP" -> 0.0 PP | I21: ='Sheet1 (2)'!K56 -> 0 | J21: ='Sheet1 (2)'!N56 -> 0
G22: Dinner | H22: =TEXT('Sheet1 (2)'!I57*100,"0.0") & " PP" -> 0.0 PP | I22: ='Sheet1 (2)'!K57 -> 0 | J22: ='Sheet1 (2)'!N57 -> 0
G23: Evening | H23: =TEXT('Sheet1 (2)'!I58*100,"0.0") & " PP" -> 0.0 PP | I23: ='Sheet1 (2)'!K58 -> 0 | J23: ='Sheet1 (2)'!N58 -> 0
G24: Late Night | H24: =TEXT('Sheet1 (2)'!I59*100,"0.0") & " PP" -> 0.0 PP | I24: ='Sheet1 (2)'!K59 -> 0 | J24: ='Sheet1 (2)'!N59 -> 0
K27: Contribution | L27: 2023 ACS | M27: YoY GC share delta
D28: ACS | F28: Mix Effect | G28: =TEXT('Sheet1 (2)'!D8*100,"0.0") & " PP" -> 3.2 PP | I28: Dayparts | J28: Breakfast | K28: =TEXT('Sheet1 (2)'!S35*100,"0.0") & " PP" -> 3.4 PP | L28: ='Sheet1 (2)'!X35 -> 13.149109 | M28: ='Sheet1 (2)'!O35 -> 0.03
D29: =TEXT('Sheet1 (2)'!D6*100,"0.00") & " PP" -> 1.34 PP | F29: Customer shift effect | J29: Lunch | K29: =TEXT('Sheet1 (2)'!S36*100,"0.0") & " PP" -> 3.8 PP | L29: ='Sheet1 (2)'!X36 -> 14.46402 | M29: ='Sheet1 (2)'!O36 -> 0.03
D30: Ticket effect | F30: (upgrading/downgrading) | J30: Snack | K30: =TEXT('Sheet1 (2)'!S37*100,"0.0") & " PP" -> -1.7 PP | L30: ='Sheet1 (2)'!X37 -> 9.6426798 | M30: ='Sheet1 (2)'!O37 -> -0.02
F31: to higher/lower ticket segment | J31: Dinner | K31: =TEXT('Sheet1 (2)'!S38*100,"0.0") & " PP" -> -4.3 PP | L31: ='Sheet1 (2)'!X38 -> 9.9181849 | M31: ='Sheet1 (2)'!O38 -> -0.05
J32: Evening | K32: =TEXT('Sheet1 (2)'!S39*100,"0.0") & " PP" -> 2.5 PP | L32: ='Sheet1 (2)'!X39 -> 14.46402 | M32: ='Sheet1 (2)'!O39 -> 0.02
J33: Late Night | K33: =TEXT('Sheet1 (2)'!S40*100,"0.0") & " PP" -> -0.6 PP | L33: ='Sheet1 (2)'!X40 -> 6.4284532 | M33: ='Sheet1 (2)'!O40 -> -0.01
K35: Contribution | L35: 2023 ACS | M35: YoY GC share delta
I36: Segment2 | J36: Breakfast | K36: =TEXT('Sheet1 (2)'!S44*100,"0.0") & " PP" -> 0.0 PP | L36: ='Sheet1 (2)'!X44 -> 0 | M36: ='Sheet1 (2)'!O44 -> 0
J37: Lunch | K37: =TEXT('Sheet1 (2)'!S45*100,"0.0") & " PP" -> 0.0 PP | L37: ='Sheet1 (2)'!X45 -> 0 | M37: ='Sheet1 (2)'!O45 -> 0
J38: Snack | K38: =TEXT('Sheet1 (2)'!S46*100,"0.0") & " PP" -> 0.0 PP | L38: ='Sheet1 (2)'!X46 -> 0 | M38: ='Sheet1 (2)'!O46 -> 0
J39: Dinner | K39: =TEXT('Sheet1 (2)'!S47*100,"0.0") & " PP" -> 0.0 PP | L39: ='Sheet1 (2)'!X47 -> 0 | M39: ='Sheet1 (2)'!O47 -> 0
J40: Evening | K40: =TEXT('Sheet1 (2)'!S48*100,"0.0") & " PP" -> 0.0 PP | L40: ='Sheet1 (2)'!X48 -> 0 | M40: ='Sheet1 (2)'!O48 -> 0
J41: Late Night | K41: =TEXT('Sheet1 (2)'!S49*100,"0.0") & " PP" -> 0.0 PP | L41: ='Sheet1 (2)'!X49 -> 0 | M41: ='Sheet1 (2)'!O49 -> 0
K43: Contribution | L43: 2023 ACS | M43: YoY GC share delta
I44: Segment2 | J44: Breakfast | K44: =TEXT('Sheet1 (2)'!S52*100,"0.0") & " PP" -> 0.0 PP | L44: ='Sheet1 (2)'!X52 -> 0 | M44: ='Sheet1 (2)'!O52 -> 0
J45: Lunch | K45: =TEXT('Sheet1 (2)'!S53*100,"0.0") & " PP" -> 0.0 PP | L45: ='Sheet1 (2)'!X53 -> 0 | M45: ='Sheet1 (2)'!O53 -> 0
J46: Snack | K46: =TEXT('Sheet1 (2)'!S54*100,"0.0") & " PP" -> 0.0 PP | L46: ='Sheet1 (2)'!X54 -> 0 | M46: ='Sheet1 (2)'!O54 -> 0
J47: Dinner | K47: =TEXT('Sheet1 (2)'!S55*100,"0.0") & " PP" -> 0.0 PP | L47: ='Sheet1 (2)'!X55 -> 0 | M47: ='Sheet1 (2)'!O55 -> 0
...

Sheet Sheet1 (2)
A1: TOTAL
B2: Sales | C2: GCS1 | D2: ACS2 | E2: ACS (delta)
A3: 2023 | B3: 481513 | C3: 41613 | D3: =B3/C3 -> 11.571216
A4: 2024 | B4: 494078 | C4: 42138 | D4: =B4/C4 -> 11.725236
A5: YoY | B5: =B4/B3-1 -> 0.02609483 | C5: =C4/C3-1 -> 0.01261625 | D5: =D4/D3-1 -> 0.01331065 | E5: =D4-D3 -> 0.1540204
A6: Contribution | B6: =SUM(C6:D6) -> 0.02609483 | C6: =C5+0.5*(C5*D5) -> 0.012700215 | D6: =D5+0.5*(D5*C5) -> 0.013394615
A8: ACS Mix contrib3 | D8: =SUM(S35:S40) -> 0.031511544
A9: ACS Within contrib4 | D9: =SUM(T35:T40) -> -0.018200894
A11: 1 GCS contribution (pp) = Base-year GCS share × Within-daypart YoY growth
A12: ACS contribution (pp) = ACS YoY % + ½ × (GCS YoY % × ACS YoY %)
A13: ACS contribution = ACS mix contribution + ACS within contribution
A14: ACS mix contribution = Change in GCS share × Base-period segment ACS
A15: ACS within contribution = Current-period GCS share × Change in segment ACS
A18: 1 GCS contribution (+1.27pp): Traffic Effect. Sales growth was driven in part by higher guest counts (+1.27pp), reflecting broad-based traffic increases.
A19: Contributions came from a combination of steady growth in large, high-share segments and outsized growth in smaller segments, which together lifted overall traffic despite some offsetting declines.
A20: 2 ACS Contribution ( +1.34pp ) — “Ticket effect” Average check growth contributed +1.34pp to sales growth, slightly more than traffic.
A21: This reflects changes in where customers purchased and how much they spent per visit, with the compounding effect between traffic and ticket allocated evenly across the two drivers.
A22: ³ ACS Mix Contribution ( +3.15pp ) — “Customer shift effect”
A23: Customer mix shifts contributed positively to average check growth (+3.15pp), as customers moved toward higher-ticket segments.
A24: This effect reflects changes in traffic allocation across segments, holding segment-level prices constant.
... A27: This offset a portion of the favorable mix impact and suggests offsetting dynamics within segments (e.g., pricing, discounting, or product mix changes).
A30: SALES | H30: GCS | Q30: ACS
C32: 2023 | E32: 2024 | J32: 2023 | L32: 2024 | N32: YoY
B33: Total contrib PP | C33: Value | D33: Share | E33: Value | F33: Share | I33: Total contrib PP | J33: Value | K33: Share | L33: Value | M33: Share | N33: YoY % | O33: YoY (delta) | R33: Total contrib PP | S33: Mix contrib PP | T33: Within contrib PP | U33: Total contrib | V33: Mix contrib | W33: Within contrib | X33: ACS value
A34: Daypart | H34: Daypart | Q34: Daypart | X34: 2023 | Y34: 2024 | Z34: ACS (delta)
A35: Breakfast | B35: =I35+R35 -> 0.066881044 | C35: 120378.25 | D35: =C35/$B$3 -> 0.25 | E35: 138341.84 | F35: =E35/$B$4 -> 0.28 | H35: Breakfast | I35: =K35*N35 -> 0.033154062 | J35: 9154.86 | K35: =J35/$C$3 -> 0.22 | L35: 10534.5 | M35: =L35/$C$4 -> 0.25 | N35: =L35/J35-1 -> 0.15070028 | O35: =M35-K35 -> 0.03 | Q35: Breakfast | R35: =U35/$D$3 -> 0.033726982 | S35: =V35/$D$3 -> 0.034090909 | T35: =W35/$D$3 -> -0.00036392708 | U35: =SUM(V35:W35) -> 0.39026218 | V35: =O35*X35 -> 0.39447326 | W35: =M35*Z35 -> -0.0042110788 | X35: =C35/J35 -> 13.149109 | Y35: =E35/L35 -> 13.132264 | Z35: =Y35-X35 -> -0.016844315
A36: Lunch | B36: =I36+R36 -> 0.066628719 | C36: 120378.25 | D36: =C36/$B$3 -> 0.25 | E36: 138341.84 | F36: =E36/$B$4 -> 0.28 | H36: Lunch | I36: =K36*N36 -> 0.032901737 | J36: 8322.6 | K36: =J36/$C$3 -> 0.2 | L36: 9691.74 | M36: =L36/$C$4 -> 0.23 | N36: =L36/J36-1 -> 0.16450869 | O36: =M36-K36 -> 0.03 | Q36: Lunch | R36: =U36/$D$3 -> 0.033726982 | S36: =V36/$D$3 -> 0.0375 | T36: =W36/$D$3 -> -0.003773018 | U36: =SUM(V36:W36) -> 0.39026218 | V36: =O36*X36 -> 0.43392059 | W36: =M36*Z36 -> -0.043658405 | X36: =C36/J36 -> 14.46402 | Y36: =E36/L36 -> 14.274201 | Z36: =Y36-X36 -> -0.18981915
A37: Snack | B37: =I37+R37 -> -0.039096031 | C37: 24075.65 | D37: =C37/$B$3 -> 0.05 | E37: 14822.34 | F37: =E37/$B$4 -> 0.03 | H37: Snack | I37: =K37*N37 -> -0.01949535 | J37: 2496.78 | K37: =J37/$C$3 -> 0.06 | L37: 1685.52 | M37: =L37/$C$4 -> 0.04 | N37: =L37/J37-1 -> -0.3249225 | O37: =M37-K37 -> -0.02 | Q37: Snack | R37: =U37/$D$3 -> -0.01960068 | S37: =V37/$D$3 -> -0.016666667 | T37: =W37/$D$3 -> -0.0029340138 | U37: =SUM(V37:W37) -> -0.2268037 | V37: =O37*X37 -> -0.1928536 | W37: =M37*Z37 -> -0.033950107 | X37: =C37/J37 -> 9.6426798 | Y37: =E37/L37 -> 8.7939271 | Z37: =Y37-X37 -> -0.84875267
A38: Dinner | B38: =I38+R38 -> -0.092887463 | C38: 144453.9 | D38: =C38/$B$3 -> 0.3 | E38: 123519.5 | F38: =E38/$B$4 -> 0.25 | H38: Dinner | I38: =K38*N38 -> -0.046215125 | J38: 14564.55 | K38: =J38/$C$3 -> 0.35 | L38: 12641.4 | M38: =L38/$C$4 -> 0.3 | N38: =L38/J38-1 -> -0.13204321 | O38: =M38-K38 -> -0.05 | Q38: Dinner | R38: =U38/$D$3 -> -0.046672337 | S38: =V38/$D$3 -> -0.042857143 | T38: =W38/$D$3 -> -0.0038151946 | U38: =SUM(V38:W38) -> -0.54005569 | V38: =O38*X38 -> -0.49590925 | W38: =M38*Z38 -> -0.04414644 | X38: =C38/J38 -> 9.9181849 | Y38: =E38/L38 -> 9.7710301 | Z38: =Y38-X38 -> -0.1471548
A39: Evening | B39: =I39+R39 -> 0.073258222 | C39: 48151.3 | D39: =C39/$B$3 -> 0.1 | E39: 74111.7 | F39: =E39/$B$4 -> 0.15 | H39: Evening | I39: =K39*N39 -> 0.021261625 | J39: 3329.04 | K39: =J39/$C$3 -> 0.08 | L39: 4213.8 | M39: =L39/$C$4 -> 0.1 | N39: =L39/J39-1 -> 0.26577031 | O39: =M39-K39 -> 0.02 | Q39: Evening | R39: =U39/$D$3 -> 0.051996598 | S39: =V39/$D$3 -> 0.025 | T39: =W39/$D$3 -> 0.026996598 | U39: =SUM(V39:W39) -> 0.60166385 | V39: =O39*X39 -> 0.28928039 | W39: =M39*Z39 -> 0.31238345 | X39: =C39/J39 -> 14.46402 | Y39: =E39/L39 -> 17.587854 | Z39: =Y39-X39 -> 3.1238345
A40: Late Night | B40: =I40+R40 -> -0.048857594 | C40: 24075.65 | D40: =C40/$B$3 -> 0.05 | E40: 4940.78 | F40: =E40/$B$4 -> 0.01 | H40: Late Night | I40: =K40*N40 -> -0.0089907 | J40: 3745.17 | K40: =J40/$C$3 -> 0.09 | L40: 3371.04 | M40: =L40/$C$4 -> 0.08 | N40: =L40/J40-1 -> -0.099896667 | O40: =M40-K40 -> -0.01 | Q40: Late Night | R40: =U40/$D$3 -> -0.039866893 | S40: =V40/$D$3 -> -0.0055555556 | T40: =W40/$D$3 -> -0.034311338 | U40: =SUM(V40:W40) -> -0.46130843 | V40: =O40*X40 -> -0.064284532 | W40: =M40*Z40 -> -0.39702389 | X40: =C40/J40 -> 6.4284532 | Y40: =E40/L40 -> 1.4656545 | Z40: =Y40-X40 -> -4.9627987
A41: Total | B41: =SUM(B35:B40) -> 0.0259269 | C41: =SUM(C35:C40) -> 481513 | D41: =SUM(D35:D40) -> 1 | E41: =SUM(E35:E40) -> 494078 | F41: =SUM(F35:F40) -> 1 | H41: Total | I41: =SUM(I35:I40) -> 0.01261625 | J41: =SUM(J35:J40) -> 41613 | K41: =SUM(K35:K40) -> 1 | L41: =SUM(L35:L40) -> 42138 | M41: =SUM(M35:M40) -> 1 | Q41: Total | R41: =SUM(R35:R40) -> 0.01331065 | U41: =SUM(U35:U40) -> 0.1540204
H43: Breakfast combined meaningful scale (over one-fifth of traffic) with strong positive growth. Breakfast was a key driver of traffic growth, contributing +3.3pp, supported by strong within-daypart growth on a large base. The rising share in 2024 reinforces that this was not a niche effect; breakfast demand strengthened and became more central to total traffic.
H44: Dinner was the largest drag on traffic, contributing −4.6pp, as declines in the largest daypart outweighed gains elsewhere. | Q44: Mix contrib: | R44: Customers shift toward/away from breakfast, holding breakfast’s price/ticket fixed at last year’s level.
R45: Interpretation: Breakfast gained traffic share (22% → 25%). Since breakfast has a relatively high ticket ($13.15), that mix shift pushes overall ACS up.
Q46: Within contrib | R46: Keep the new mix (2024 shares), and ask: did breakfast ticket change inside breakfast?
R47: Breakfast’s ticket fell slightly (13.15 → 13.13), so within-breakfast changes slightly pull overall ACS down.
Q50: “Average check increased by 1.33% year over year. When we decompose that change, X% came from customers shifting across segments, and Y% came from higher ticket within segments.

Sheet Sheet1
B1: Sales | C1: GCS | D1: ACS | E1: ACS (delta)
A2: 2023 | B2: 481513 | C2: 41613 | D2: =B2/C2 -> 11.571216
A3: 2024 | B3: 494078 | C3: 42138 | D3: =B3/C3 -> 11.725236
A4: YoY | B4: =B3/B2-1 -> 0.02609483 | C4: =C3/C2-1 -> 0.01261625 | D4: =D3/D2-1 -> 0.01331065 | E4: =D3-D2 -> 0.1540204
A5: Contribution | C5: =C4+0.5*(C4*D4) -> 0.012700215 | D5: =D4+0.5*(D4*C4) -> 0.013394615
A7: Mix contrib | D7: =SUM(Z17:Z22) -> 0.031511544
A8: Within contrib | D8: =SUM(AA17:AA22) -> -0.018200894
A9: “Average check increased by 1.33% year over year. When we decompose that change, X% came from customers shifting across segments, and Y% came from higher ticket within segments.
B13: 2023 | J13: 2024 | Q13: YoY | V13: Contribution
B14: Sales | D14: GCS | F14: ACS | J14: Sales | L14: GCS | N14: ACS | Q14: Sales | R14: GCS | S14: ACS | V14: GCS | W14: ACS | AC14: Sales
B15: Value | C15: Share | D15: Value | E15: Share | F15: Value | G15: Share | J15: Value | K15: Share | L15: Value | M15: Share | N15: Value | O15: Share
A16: Daypart | I16: Daypart | Q16: Sales | R16: GCS | S16: GCS (delta) | T16: ACS (delta) | W16: Mix contrib | X16: Within contrib | Y16: Total contrib | Z16: Mix contrib PP | AA16: Within contrib PP | AB16: Total contrib PP
A17: Breakfast | B17: 120378.25 | C17: =B17/$B$2 -> 0.25 | D17: 9154.86 | E17: =D17/$C$2 -> 0.22 | F17: =B17/D17 -> 13.149109 | I17: Breakfast | J17: 138341.84 | K17: =J17/$B$3 -> 0.28 | L17: 10534.5 | M17: =L17/$C$3 -> 0.25 | N17: =J17/L17 -> 13.132264 | R17: =L17/D17-1 -> 0.15070028 | S17: =M17-E17 -> 0.03 | T17: =N17-F17 -> -0.016844315 | V17: =E17*R17 -> 0.033154062 | W17: =S17*F17 -> 0.39447326 | X17: =M17*T17 -> -0.0042110788 | Y17: =SUM(W17:X17) -> 0.39026218 | Z17: =W17/$D$2 -> 0.034090909 | AA17: =X17/$D$2 -> -0.00036392708 | AB17: =Y17/$D$2 -> 0.033726982 | AC17: =V17+AB17 -> 0.066881044
A18: Lunch | B18: 120378.25 | C18: =B18/$B$2 -> 0.25 | D18: 8322.6 | E18: =D18/$C$2 -> 0.2 | F18: =B18/D18 -> 14.46402 | I18: Lunch | J18: 138341.84 | K18: =J18/$B$3 -> 0.28 | L18: 9691.74 | M18: =L18/$C$3 -> 0.23 | N18: =J18/L18 -> 14.274201 | R18: =L18/D18-1 -> 0.16450869 | S18: =M18-E18 -> 0.03 | T18: =N18-F18 -> -0.18981915 | V18: =E18*R18 -> 0.032901737 | W18: =S18*F18 -> 0.43392059 | X18: =M18*T18 -> -0.043658405 | Y18: =SUM(W18:X18) -> 0.39026218 | Z18: =W18/$D$2 -> 0.0375 | AA18: =X18/$D$2 -> -0.003773018 | AB18: =Y18/$D$2 -> 0.033726982 | AC18: =V18+AB18 -> 0.066628719
A19: Snack | B19: 24075.65 | C19: =B19/$B$2 -> 0.05 | D19: 2496.78 | E19: =D19/$C$2 -> 0.06 | F19: =B19/D19 -> 9.6426798 | I19: Snack | J19: 14822.34 | K19: =J19/$B$3 -> 0.03 | L19: 1685.52 | M19: =L19/$C$3 -> 0.04 | N19: =J19/L19 -> 8.7939271 | R19: =L19/D19-1 -> -0.3249225 | S19: =M19-E19 -> -0.02 | T19: =N19-F19 -> -0.84875267 | V19: =E19*R19 -> -0.01949535 | W19: =S19*F19 -> -0.1928536 | X19: =M19*T19 -> -0.033950107 | Y19: =SUM(W19:X19) -> -0.2268037 | Z19: =W19/$D$2 -> -0.016666667 | AA19: =X19/$D$2 -> -0.0029340138 | AB19: =Y19/$D$2 -> -0.01960068 | AC19: =V19+AB19 -> -0.039096031
A20: Dinner | B20: 144453.9 | C20: =B20/$B$2 -> 0.3 | D20: 14564.55 | E20: =D20/$C$2 -> 0.35 | F20: =B20/D20 -> 9.9181849 | I20: Dinner | J20: 123519.5 | K20: =J20/$B$3 -> 0.25 | L20: 12641.4 | M20: =L20/$C$3 -> 0.3 | N20: =J20/L20 -> 9.7710301 | R20: =L20/D20-1 -> -0.13204321 | S20: =M20-E20 -> -0.05 | T20: =N20-F20 -> -0.1471548 | V20: =E20*R20 -> -0.046215125 | W20: =S20*F20 -> -0.49590925 | X20: =M20*T20 -> -0.04414644 | Y20: =SUM(W20:X20) -> -0.54005569 | Z20: =W20/$D$2 -> -0.042857143 | AA20: =X20/$D$2 -> -0.0038151946 | AB20: =Y20/$D$2 -> -0.046672337 | AC20: =V20+AB20 -> -0.092887463
A21: Evening | B21: 48151.3 | C21: =B21/$B$2 -> 0.1 | D21: 3329.04 | E21: =D21/$C$2 -> 0.08 | F21: =B21/D21 -> 14.46402 | I21: Evening | J21: 74111.7 | K21: =J21/$B$3 -> 0.15 | L21: 4213.8 | M21: =L21/$C$3 -> 0.1 | N21: =J21/L21 -> 17.587854 | R21: =L21/D21-1 -> 0.26577031 | S21: =M21-E21 -> 0.02 | T21: =N21-F21 -> 3.1238345 | V21: =E21*R21 -> 0.021261625 | W21: =S21*F21 -> 0.28928039 | X21: =M21*T21 -> 0.31238345 | Y21: =SUM(W21:X21) -> 0.60166385 | Z21: =W21/$D$2 -> 0.025 | AA21: =X21/$D$2 -> 0.026996598 | AB21: =Y21/$D$2 -> 0.051996598 | AC21: =V21+AB21 -> 0.073258222
A22: Late Night | B22: 24075.65 | C22: =B22/$B$2 -> 0.05 | D22: 3745.17 | E22: =D22/$C$2 -> 0.09 | F22: =B22/D22 -> 6.4284532 | I22: Late Night | J22: 4940.78 | K22: =J22/$B$3 -> 0.01 | L22: 3371.04 | M22: =L22/$C$3 -> 0.08 | N22: =J22/L22 -> 1.4656545 | R22: =L22/D22-1 -> -0.099896667 | S22: =M22-E22 -> -0.01 | T22: =N22-F22 -> -4.9627987 | V22: =E22*R22 -> -0.0089907 | W22: =S22*F22 -> -0.064284532 | X22: =M22*T22 -> -0.39702389 | Y22: =SUM(W22:X22) -> -0.46130843 | Z22: =W22/$D$2 -> -0.0055555556 | AA22: =X22/$D$2 -> -0.034311338 | AB22: =Y22/$D$2 -> -0.039866893 | AC22: =V22+AB22 -> -0.048857594
A23: Total | B23: =SUM(B17:B22) -> 481513 | C23: =SUM(C17:C22) -> 1 | D23: =SUM(D17:D22) -> 41613 | E23: =SUM(E17:E22) -> 1 | J23: =SUM(J17:J22) -> 494078 | K23: =SUM(K17:K22) -> 1 | L23: =SUM(L17:L22) -> 42138 | M23: =SUM(M17:M22) -> 1 | V23: =SUM(V17:V22) -> 0.01261625 | Y23: =SUM(Y17:Y22) -> 0.1540204 | AB23: =SUM(AB17:AB22) -> 0.01331065 | AC23: =SUM(AC17:AC22) -> 0.0259269
W25: Mix contrib: | X25: Customers shift toward/away from breakfast, holding breakfast’s price/ticket fixed at last year’s level.
X26: Interpretation: Breakfast gained traffic share (22% → 25%). Since breakfast has a relatively high ticket ($13.15), that mix shift pushes overall ACS up.
W27: Within contrib | X27: Keep the new mix (2024 shares), and ask: did breakfast ticket change inside breakfast?
X28: Breakfast’s ticket fell slightly (13.15 → 13.13), so within-breakfast changes slightly pull overall ACS down.

Sheet Sheet2 (2)
H2: 2023 share | I2: 2024 YoY
C3: GCS | E3: Dayparts | F3: Breakfast | G3: 1.2 PP | H3: 0.055 | I3: 0.224
C4: 1.2 PP | F4: Lunch | G4: 0.0 PP | H4: 0.207 | I4: -0.001
F5: Snack | G5: -0.1PP | H5: 0.22 | I5: -0.004
F6: Dinner | G6: 0.0 PP | H6: 0.256 | I6: -0.002
F7: Evening | G7: 0.0 PP | H7: 0.179 | I7: -0.001
F8: Late Night | G8: 0.2 PP | H8: 0.084 | I8: 0.027
E10: Channels | F10: Mobile | G10: 2.3 PP
F11: Delivery | G11: 0.6 PP
F12: Front Counter | G12: -2.4 PP
A13: SALES | F13: Drive Thru | G13: -2.4 PP
A14: 0.0261 | F14: Kiosk | G14: 3.9 PP
F15: Mccafe | G15: -0.1 PP
A16: YoY 23 vs 24 | F16: Other | G16: -0.6 PP
E18: Product Categories | F18: Dessert | G18: -0.3 PP
F19: Beef | G19: 1.0 PP
F20: Chicken | G20: -0.2 PP
F21: Drink | G21: -0.2 PP
F22: Others | G22: 0.9 PP
C25: ACS | E25: Dayparts | F25: Breakfast
C26: 1.2 PP | F26: Lunch
F27: Snack
F28: Dinner
F29: Evening
F30: Late Night
E32: Channels | F32: Mobile
F33: Delivery
F34: Front Counter
F35: Drive Thru
F36: Kiosk
F37: Mccafe
F38: Other
E41: Product Categories | F41: Dessert
F42: Beef
F43: Chicken
F44: Drink
F45: Others
